Inside fun().
caught in main.

Process finished with exit code 0